Workbook
Name Processus: [1]Menu!$A$2:$A$11

Sheet base_Sage bi reporting
A1: Contrôle chiffre d'affaires
A3: PRENDRE CHIFFRES DEPUIS LE DEBUT DE L'ANNEE : HA + OD
A6: Sélection
A7: Dossier | B7: *
A8: Société | B8: SARL SEVT
A9: Compte
A10: Exercice | B10: Du 01/10/25 au 30/09/26
A11: Mois | B11: *
A12: Journal | B12: VT
A14: JOURNAL VENTES
A15: =_xll.Assistant.XL.RIK_SR("INF02__0_D=16x2_O=7_0_0_0_0_1-1;INF02@E=0,S=1023,G=1,T=0_0,P=-1_,C=0,L=Mois@E=0,S=1001|1,G=1,T=0_0,P=-1_,C=0,L=Compte Général - Code@E=1,S=1031,L=Solde Tenue de Compte,O=NF='Nombre'@R=A,S=1000,V={0}:R=B,S=1012|1,V=VT:R=C,S=1,V={1}:",$B$8,$B$10)
B17: Mois
A18: Compte Général - Code | B18: 10
A19: 411000 | B19: -1431370.4
A20: 445669 | B20: -538.37
A21: 445715 | B21: 5556.74
A22: 445716 | B22: 75619.45
A23: 445719 | B23: 538.37
A24: 706110 | B24: 111456.16
A25: 706118 | B25: 180772.77
A26: 707000 | B26: 23887.92
A27: 707050 | B27: 267113.52
A28: 707051 | B28: 469898.66
A29: 707052 | B29: 179207.91
A30: 708518 | B30: 89764.17
A31: 708519 | B31: 28093.1
A32: Total | B32: 0
B42: 10 | C42: 11 | D42: 12 | E42: 1 | F42: 2 | G42: 3 | H42: 4 | I42: 5 | J42: 6 | K42: 7 | L42: 8 | M42: 9 | N42: Total
A43: CA - saisir en dur | B43: 1350194.2 | N43: =SUM(B43:M43) -> 1350194.2
A44: Avoirs | B44: 67101.23 | N44: =SUM(B44:M44) -> 67101.23
A45: % | B45: =IFERROR(B44/B43,0) -> 0.049697465 | C45: =IFERROR(C44/C43,0) -> 0 | D45: =IFERROR(D44/D43,0) -> 0 | E45: =IFERROR(E44/E43,0) -> 0 | F45: =IFERROR(F44/F43,0) -> 0 | G45: =IFERROR(G44/G43,0) -> 0 | H45: =IFERROR(H44/H43,0) -> 0 | I45: =IFERROR(I44/I43,0) -> 0 | ... N45: =IFERROR(N44/N43,0) -> 0.049697465
A52: JOURNAL VENTES - AVOIRS
A53: =_xll.Assistant.XL.RIK_SR("INF02__0_D=4x3_O=7_0_0_0_0_1-1;INF02@E=0,S=1023,G=1,T=0_0,P=-1_,C=0,L=Mois@E=0,S=1001|1,G=1,T=0_0,P=-1_,C=0,L=Compte Général - Code:E=0,S=1003|2,G=1,T=0_0,P=-1_,C=0,L=Tiers - Nom@E=1,S=1031,L=Solde Tenue de Compte,O=NF='"&"Nombre'@R=A,S=1000,V={0}:R=B,S=1012|1,V=VT:R=C,S=1,V={1}:R=D,S=1011,V=a*:R=E,S=1001|1,V=411000:",$B$8,$B$10)
C55: Mois
A56: Compte Général - Code | B56: Tiers - Nom | C56: 10
A57: 411000 | B57: ABO TRADING | C57: 67101.26
A58: Total 411000 | C58: 67101.26

Sheet base_Suivi autre
A1: SUIVI CA
B3: 45931 | C3: 45962 | D3: 45992 | E3: 46023 | F3: 46054 | G3: 46082 | H3: 46113 | I3: 46143 | J3: 46174 | K3: 46204 | L3: 46235 | M3: 46266 | N3: TOTAL
A4: CA Total (€) | B4: ='base_Sage bi reporting'!B43 -> 1350194.2 | C4: 489821.96 | D4: ='base_Sage bi reporting'!D43 -> 0 | E4: ='base_Sage bi reporting'!E43 -> 0 | F4: ='base_Sage bi reporting'!F43 -> 0 | G4: ='base_Sage bi reporting'!G43 -> 0 | H4: ='base_Sage bi reporting'!H43 -> 0 | I4: ='base_Sage bi reporting'!I43 -> 0 | J4: ='base_Sage bi reporting'!J43 -> 0 | K4: ='base_Sage bi reporting'!K43 -> 0 | ... N4: ='base_Sage bi reporting'!N43 -> 1350194.2
A5: Avoirs / complément fac Total (€) | B5: ='base_Sage bi reporting'!B44 -> 67101.23 | C5: 0 | D5: ='base_Sage bi reporting'!D44 -> 0 | E5: ='base_Sage bi reporting'!E44 -> 0 | F5: ='base_Sage bi reporting'!F44 -> 0 | G5: ='base_Sage bi reporting'!G44 -> 0 | H5: ='base_Sage bi reporting'!H44 -> 0 | I5: ='base_Sage bi reporting'!I44 -> 0 | J5: ='base_Sage bi reporting'!J44 -> 0 | K5: ='base_Sage bi reporting'!K44 -> 0 | ... N5: ='base_Sage bi reporting'!N44 -> 67101.23
A6: Taux avoir | B6: ='base_Sage bi reporting'!B45 -> 0.049697465 | C6: ='base_Sage bi reporting'!C45 -> 0 | D6: ='base_Sage bi reporting'!D45 -> 0 | E6: ='base_Sage bi reporting'!E45 -> 0 | F6: ='base_Sage bi reporting'!F45 -> 0 | G6: ='base_Sage bi reporting'!G45 -> 0 | H6: ='base_Sage bi reporting'!H45 -> 0 | I6: ='base_Sage bi reporting'!I45 -> 0 | ... N6: ='base_Sage bi reporting'!N45 -> 0.049697465
A9: SUIVI DOSSIERS ACTIFS ET AUDITS REALISES
B11: =B3 -> 45931 | C11: =C3 -> 45962 | D11: =D3 -> 45992 | E11: =E3 -> 46023 | F11: =F3 -> 46054 | G11: =G3 -> 46082 | H11: =H3 -> 46113 | I11: =I3 -> 46143 | ... M11: =M3 -> 46266 | N11: Dernieres valeurs
A12: Nb dossiers | B12: 76 | C12: 76 | D12: 76 | N12: =IFERROR(LOOKUP(9^9,B12:M12),0) -> 76
A13: Nb dossiers conformes | B13: 75 | C13: 75 | D13: 75 | N13: =IFERROR(LOOKUP(9^9,B13:M13),0) -> 75 | P13: Saisir manuellement
A14: Taux de dossier à jour | B14: =IFERROR(B13/B12,0) -> 0.98684211 | C14: =IFERROR(C13/C12,0) -> 0.98684211 | D14: =IFERROR(D13/D12,0) -> 0.98684211 | E14: =IFERROR(E13/E12,0) -> 0 | F14: =IFERROR(F13/F12,0) -> 0 | G14: =IFERROR(G13/G12,0) -> 0 | H14: =IFERROR(H13/H12,0) -> 0 | I14: =IFERROR(I13/I12,0) -> 0 | ... N14: =IFERROR(N13/N12,0) -> 0.98684211
A15: Source :
A16: Y:\PM1 - Manager le systéme qualité\5 - Enregistrements\Registre de numérotation dossiers et documents\Exercice_Registre numérotation DOSSIERS COURRIERS.xls
A19: SUIVI DU CONTRÔLE DES DOCUMENTS FIGURANT DANS LE DOSSIER QUALITE
B21: =+B11 -> 45931 | C21: =+C11 -> 45962 | D21: =+D11 -> 45992 | E21: =+E11 -> 46023 | F21: =+F11 -> 46054 | G21: =+G11 -> 46082 | H21: =+H11 -> 46113 | I21: =+I11 -> 46143 | ... M21: =+M11 -> 46266 | N21: Dernieres valeurs
A22: Nb documents actifs | B22: 179 | C22: 179 | D22: 179 | N22: =IFERROR(LOOKUP(9^9,B22:M22),0) -> 179
A23: Nb documents actifs vérifiés et conformes | B23: 0 | C23: 0 | D23: 0 | N23: =IFERROR(LOOKUP(9^9,B23:M23),0) -> 0 | P23: Saisir manuellement
A24: Taux de dossier à jour | B24: =IFERROR(B23/B22,0) -> 0 | C24: =IFERROR(C23/C22,0) -> 0 | D24: =IFERROR(D23/D22,0) -> 0 | E24: =IFERROR(E23/E22,0) -> 0 | F24: =IFERROR(F23/F22,0) -> 0 | G24: =IFERROR(G23/G22,0) -> 0 | H24: =IFERROR(H23/H22,0) -> 0 | I24: =IFERROR(I23/I22,0) -> 0 | ... N24: =IFERROR(N23/N22,0) -> 0
A25: Source :
A26: "Y:\PM1 - Manager le systéme qualité\5 - Enregistrements\Registre de numérotation dossiers et documents\Exercice_ Registre de suivi de numérotation des documents SMQ.xls"
A29: SUIVI DES FACTURES RECUES PAR COURRER
B31: =+B3 -> 45931 | C31: =+C3 -> 45962 | D31: =+D3 -> 45992 | E31: =+E3 -> 46023 | F31: =+F3 -> 46054 | G31: =+G3 -> 46082 | H31: =+H3 -> 46113 | I31: =+I3 -> 46143 | ... M31: =+M3 -> 46266 | N31: Dernieres valeurs
A32: XXX | N32: =IFERROR(LOOKUP(9^9,B32:M32),0) -> 0
A33: XXX
A34: XXX
A35: XXX
A36: XXX
A37: XXX
A38: XXX
A39: XXX | N39: =IFERROR(LOOKUP(9^9,B39:M39),0) -> 0
A40: Total | B40: =SUM(B32:B39) -> 0 | C40: =SUM(C32:C39) -> 0 | D40: =SUM(D32:D39) -> 0 | E40: =SUM(E32:E39) -> 0 | F40: =SUM(F32:F39) -> 0 | G40: =SUM(G32:G39) -> 0 | H40: =SUM(H32:H39) -> 0 | I40: =SUM(I32:I39) -> 0 | ... M40: =SUM(M32:M39) -> 0 | N40: =IFERROR(LOOKUP(9^9,B40:M40),0) -> 0

Sheet SYNTHESE PDCA Indicateurs RSE
C1: PDCA - 2025-2026 | BI1: Réf doc | BJ1: PM1 F 010
BI2: Rév | BJ2: 2
BI3: MAJ le | BJ3: 45804
T4: Lien dans fichier
A5: (*) ABO France a choisi de ne pas mettre d'actions en place
A6: Enjeux Politique Qualité | C6: PLAN (Objectifs) | D6: N° Risque/Opportunité | E6: Processus | F6: DO (Actions) | J6: Check (Indicateur) | AA6: Act | AE6: Enjeux Politique Qualité | AG6: PLAN (Objectifs) | AH6: N° Risque/Opportunité | AI6: Processus | AJ6: DO (Actions) | AN6: Check (Indicateur) | BE6: Exercice 24-25
A7: N° | B7: Libellé | C7: Objectifs | F7: Actions | G7: N° Action | H7: Qui | I7: Délai | J7: Indicateurs | K7: Cible | L7: Fréquence | M7: Source indicateur | N7: 45931 | O7: 45962 | P7: 45992 | Q7: 46023 | R7: 46054 | S7: 46082 | T7: 46113 | U7: 46143 | V7: 46174 | W7: 46204 | X7: 46235 | Y7: 46266 | Z7: Indicateurs à date | AA7: Verrouillage RDD | AB7: Indictaurs atteint | AE7: N° | AF7: Libellé | AG7: Objectifs | AJ7: Actions | AK7: N° Action | AL7: Qui | AM7: Délai | AN7: Indicateurs | AO7: Cible | AP7: Sens feu | AQ7: Fréquence | AR7: Source indicateur | AS7: 45566 | AT7: 45597 | AU7: 45627 | AV7: 45658 | AW7: 45689 | AX7: 45717 | AY7: 45748 | AZ7: 45778 | BA7: 45809 | BB7: 45839 | BC7: 45870 | BD7: 45901 | BE7: Indicateurs à date | BF7: Verrouillage RDD | BG7: Indictaurs atteint | BH7: Tendance
A9: ECONOMIE / PILOTAGE | AE9: ECONOMIE / PILOTAGE
A10: 1 | B10: Assurer la pérennité de l'entreprise | C10: O1 -Améliorer l'organisation interne | D10: 1 | E10: PR3 | F10: Eviter les erreurs de facturation | G10: * | H10: RD | I10: Permanent | J10: Part montant avoirs/complément vs chiffre d'affaires externe | K10: 0.01 | L10: Mensuelle | M10: Onglet suivi autre | N10: ='base_Suivi autre'!B6 -> 0.049697465 | O10: ='base_Suivi autre'!C6 -> 0 | P10: ='base_Suivi autre'!D6 -> 0 | Q10: ='base_Suivi autre'!E6 -> 0 | R10: ='base_Suivi autre'!F6 -> 0 | S10: ='base_Suivi autre'!G6 -> 0 | T10: ='base_Suivi autre'!H6 -> 0 | U10: ='base_Suivi autre'!I6 -> 0 | ... Z10: ='base_Suivi autre'!N6 -> 0.049697465 | AE10: 1 | AF10: Assurer la pérennité de l'entreprise | AG10: O1 -Améliorer l'organisation interne | AH10: 1 | AI10: PR3 | AJ10: Eviter les erreurs de facturation | AK10: * | AL10: RD | AM10: Permanent | AN10: Part montant avoirs/complément vs chiffre d'affaires externe | AO10: 0.01 | AP10: + | AQ10: Mensuelle | AR10: Onglet suivi autre | AS10: 0 | AT10: 0.012608964 | AU10: 0.023487253 | AV10: 0 | AW10: 0.038912818 | AX10: 0.051189947 | AY10: 0.00087607536 | AZ10: 0.00084272577 | BA10: 0.0011732665 | BB10: 0 | BC10: 0.010812259 | BD10: 0 | BE10: 0.012336217 | BF10: 0.01 | BG10: 0
D11: 1 | E11: PR1 | F11: Avoir des dossiers clients numérisés complets | G11: * | H11: AE | I11: Permanent | J11: Dossiers clients actifs complets | K11: 1 | L11: Mensuelle | M11: Onglet suivi autre | N11: ='base_Suivi autre'!B14 -> 0.98684211 | O11: ='base_Suivi autre'!C14 -> 0.98684211 | P11: ='base_Suivi autre'!D14 -> 0.98684211 | Q11: ='base_Suivi autre'!E14 -> 0 | R11: ='base_Suivi autre'!F14 -> 0 | S11: ='base_Suivi autre'!G14 -> 0 | T11: ='base_Suivi autre'!H14 -> 0 | U11: ='base_Suivi autre'!I14 -> 0 | ... Z11: ='base_Suivi autre'!N14 -> 0.98684211 | AH11: 1 | AI11: PR1 | AJ11: Avoir des dossiers clients numérisés complets | AK11: * | AL11: AE | AM11: Permanent | AN11: Dossiers clients actifs complets | AO11: 1 | AP11: - | AQ11: Mensuelle | AR11: Onglet suivi autre | AS11: 1 | AT11: 0.96153846 | AU11: 0.96153846 | AV11: 0.94666667 | AW11: 0.96 | AX11: 0.94736842 | AY11: 0.96052632 | AZ11: 0.96052632 | BA11: 0.95652174 | BB11: 0.95652174 | BC11: 0 | BD11: 0 | BE11: 0.95652174 | BF11: 1 | BG11: 0
D12: 1 | E12: PM1 | F12: Disposer d'une documentation à jour | G12: * | H12: AE | I12: 45930 | J12: Taux de conformité de la documentation mise à disposition dans le lecteur qualité | K12: 1 | L12: Annuelle | M12: Onglet suivi autre | N12: ='base_Suivi autre'!B24 -> 0 | O12: ='base_Suivi autre'!C24 -> 0 | P12: ='base_Suivi autre'!D24 -> 0 | Q12: ='base_Suivi autre'!E24 -> 0 | R12: ='base_Suivi autre'!F24 -> 0 | S12: ='base_Suivi autre'!G24 -> 0 | T12: ='base_Suivi autre'!H24 -> 0 | U12: ='base_Suivi autre'!I24 -> 0 | ... Z12: ='base_Suivi autre'!N24 -> 0 | AH12: 1 | AI12: PM1 | AJ12: Disposer d'une documentation à jour | AK12: * | AL12: AE | AM12: 45930 | AN12: Taux de conformité de la documentation mise à disposition dans le lecteur qualité | AO12: 1 | AP12: + | AQ12: Annuelle | AR12: Onglet suivi autre | AS12: 0 | AT12: 0 | AU12: 0 | AV12: 0 | AW12: 0 | AX12: 0 | AY12: 0 | AZ12: 0.46067416 | BA12: 1 | BB12: 1 | BC12: 1 | BD12: 1 | BE12: 1 | BF12: 1 | BG12: 1
D13: 1 | E13: PM1 | F13: Effectuer les tâches en temps et en heure | G13: * | H13: AE | I13: Permanent | J13: Suivi des actions en retard dans le pilotage de l'activité | K13: 0 | L13: Mensuelle | M13: "Y:\PM1 - Manager le systéme qualité\5 - Enregistrements\Pilotage de l'activité\2023-2024_Pilotage de l'activité.xls" //Taux de retard - Fichier pilotage de l'activité | N13: 0.0231 | O13: 0.057692308 | P13: 0.057692308 | Z13: =IFERROR(LOOKUP(9^9,N13:Y13),0) -> 0.057692308 | AH13: 1 | AI13: PM1 | AJ13: Effectuer les tâches en temps et en heure | AK13: * | AL13: AE | AM13: Permanent | AN13: Suivi des actions en retard dans le pilotage de l'activité | AO13: 0 | AP13: - | AQ13: Mensuelle | AR13: "Y:\PM1 - Manager le systéme qualité\5 - Enregistrements\Pilotage de l'activité\2023-2024_Pilotage de l'activité.xls" //Taux de retard - Fichier pilotage de l'activité | AS13: 0.0125 | AT13: 0.0123 | AU13: 0.03 | AV13: 0.23 | AW13: 0.0308 | AX13: 0.047297297 | AY13: 0.0273 | AZ13: 0 | BA13: 0 | BB13: 0.095454545 | BC13: 0 | BD13: 0 | BE13: 0 | BF13: 0 | BG13: 1
C14: O2- Garantir la conformité légale et réglementaire | D14: 1 | E14: PR2 | F14: Assurer la tracabilité du déchet | G14: 1444 | H14: MR | I14: Permanent | J14: Nombre de BSD non reçus | K14: 0 | L14: Mensuelle | M14: Access indicateur BSD | N14: 51 | O14: 16 | Z14: =IFERROR(LOOKUP(9^9,N14:Y14),0) -> 16 | AG14: O2- Garantir la conformité légale et réglementaire | AH14: 1 | AI14: PR2 | AJ14: Assurer la tracabilité du déchet | AK14: 1444 | AL14: MR | AM14: Permanent | AN14: Nombre de BSD non traités en retard non justifiés - Nombre de BSD non reçus | AO14: 0 | AP14: + | AQ14: Mensuelle | AR14: Access indicateur BSD | AS14: 7 | AT14: 10 | AU14: 49 | AV14: 41 | AW14: 46 | AX14: 23 | AY14: 67 | AZ14: 37 | BA14: 49 | BB14: 27 | BC14: 2 | BD14: 15 | BE14: 15 | BF14: 0 | BG14: 0
D15: 6, 7 | E15: PS2 | F15: Mesurer la conformité de notre infrastructure | G15: * | H15: MR | I15: Permanent | J15: Taux de conformité de nos ressources | K15: 1 | L15: Mensuelle | M15: "Y:\PS2 - Gérer les Autres Ressources\5 - Enregistrements\Inventaire ressources autres\2024_07_25 Liste ressources autres.xlsx" Conformité des ressources disponibles | N15: 1 | O15: 1 | P15: 1 | Z15: =IFERROR(LOOKUP(9^9,N15:Y15),0) -> 1 | AH15: 6, 7 | AI15: PS2 | AJ15: Mesurer la conformité de notre infrastructure | AK15: * | AL15: MR | AM15: Permanent | AN15: Taux de conformité de nos ressources | AO15: 1 | AP15: - | AQ15: Mensuelle | AR15: "Y:\PS2 - Gérer les Autres Ressources\5 - Enregistrements\Inventaire ressources autres\2024_07_25 Liste ressources autres.xlsx" Conformité des ressources disponibles | AS15: 0.99 | AT15: 0.98 | AU15: 0.99 | AV15: 0.99 | AW15: 0.99 | AX15: 0.99 | AY15: 0.99 | AZ15: 0.99 | BA15: 0.99 | BB15: 0.99 | BC15: 0.99 | BD15: 1 | BE15: 1 | BF15: 1 | BG15: 1
D16: 9 | E16: PR3 | F16: Préparer la facturation electronique | G16: 1150 | H16: RD | I16: 45930 | J16: Part des fiches fournisseurs complétes dans SAGE | K16: 1 | L16: Mensuelle | M16: Déclaratif | N16: 1 | O16: 1 | Z16: =IFERROR(LOOKUP(9^9,N16:Y16),0) -> 1 | AH16: 9 | AI16: PR3 | AJ16: Préparer la facturation electronique | AK16: 1150 | AL16: RD | AM16: 45930 | AN16: Part des fiches fournisseurs complétes dans SAGE | AO16: 1 | AP16: - | AQ16: Mensuelle | AR16: Déclaratif | AS16: 1 | AT16: 1 | AU16: 1 | AV16: 1 | AW16: 1 | AX16: 1 | AY16: 1 | AZ16: 1 | BA16: 1 | BB16: 1 | BC16: 1 | BD16: 1 | BE16: 1 | BF16: 1 | BG16: 1
D17: 9 | E17: PR3 | F17: Préparer la facturation electronique | G17: 1150 | H17: RD | I17: 45930 | J17: Part des fiches clients completés dans SAGE | K17: 1 | L17: Mensuelle | M17: Déclaratif | N17: 1 | O17: 1 | Z17: =IFERROR(LOOKUP(9^9,N17:Y17),0) -> 1 | AH17: 9 | AI17: PR3 | AJ17: Préparer la facturation electronique | AK17: 1150 | AL17: RD | AM17: 45930 | AN17: Part des fiches clients completés dans SAGE | AO17: 1 | AP17: - | AQ17: Mensuelle | AR17: Déclaratif | AS17: 1 | AT17: 1 | AU17: 1 | AV17: 1 | AW17: 1 | AX17: 1 | AY17: 1 | AZ17: 1 | BA17: 1 | BB17: 1 | BC17: 1 | BD17: 1 | BE17: 1 | BF17: 1 | BG17: 1
D18: 1, 12 | E18: PM1 | F18: Analyser les évolutions légales et réglementaires | G18: 1444 | H18: AE | I18: Permanent | J18: Taux de conformité réglementaire | K18: 1 | L18: Mensuelle | M18: "Y:\PM1 - Manager le systéme qualité\5 - Enregistrements\Réglementation\Examen conformité\2024_Liste exigences applicables et examen de la conformité.xls" - Fichier évaluation conformité | N18: 0.95 | O18: 0.909 | P18: 0.909 | Z18: =IFERROR(LOOKUP(9^9,N18:Y18),0) -> 0.909 | AH18: 1, 12 | AI18: PM1 | AJ18: Analyser les évolutions légales et réglementaires | AK18: 1444 | AL18: AE | AM18: Permanent | AN18: Taux de conformité réglementaire | AO18: 1 | AP18: - | AQ18: Mensuelle | AR18: "Y:\PM1 - Manager le systéme qualité\5 - Enregistrements\Réglementation\Examen conformité\2024_Liste exigences applicables et examen de la conformité.xls" - Fichier évaluation conformité | AS18: 0.95 | AT18: 0.95 | AU18: 0.905 | AV18: 0.905 | AW18: 0.929 | AX18: 0.929 | AY18: 0.929 | AZ18: 0.929 | BA18: 0.929 | BB18: 0.929 | BC18: 0.952 | BD18: 0.952 | BE18: 0.952 | BF18: 1 | BG18: 0
C19: O3 - Maintenir l'activité actuelle et conquérir de nouvelles parts de marché | D19: 1 | E19: PR1 | F19: Gagner de nouveaux segments de marché | G19: 1444 | H19: AE | I19: Permanent | J19: Taux de transformation des devis | K19: 0.61 | L19: Annuelle | M19: "Y:\PM1 - Manager le systéme qualité\5 - Enregistrements\Registre de numérotation dossiers et documents\2024_Registre numérotation DOSSIERS COURRIERS.xls" //Taux de transformation des devis | N19: 0.57142857 | O19: 0.57142857 | P19: 0.57142857 | Z19: =IFERROR(LOOKUP(9^9,N19:Y19),0) -> 0.57142857 | AG19: O3 - Maintenir l'activité actuelle et conquérir de nouvelles parts de marché | AH19: 1 | AI19: PR1 | AJ19: Gagner de nouveaux segments de marché | AK19: 1444 | AL19: AE | AM19: Permanent | AN19: Taux de transformation des devis | AO19: 0.61 | AP19: - | AQ19: Annuelle | AR19: "Y:\PM1 - Manager le systéme qualité\5 - Enregistrements\Registre de numérotation dossiers et documents\2024_Registre numérotation DOSSIERS COURRIERS.xls" //Taux de transformation des devis | AS19: 0 | AT19: 0 | AU19: 0.1 | AV19: 0.17 | AW19: 0.15 | AX19: 0.13 | AY19: 0.24 | AZ19: 0.32 | BA19: 0.35714286 | BB19: 0.35714286 | BC19: 0.38 | BD19: 0.42 | BE19: 0.42 | BF19: 0.61 | BG19: 0
D20: 1 | E20: PM1 | F20: Atteindre la performance économique attendue | G20: 1444 | H20: AE | I20: Permanent | J20: Suivi réalisé vs budget EBITDA | K20: 1 | L20: Mensuelle | M20: Situations mensuelles | N20: 0.16 | O20: 0.2 | Z20: =IFERROR(LOOKUP(9^9,N20:Y20),0) -> 0.2 | AH20: 1 | AI20: PM1 | AJ20: Atteindre la performance économique attendue | AK20: 1444 | AL20: AE | AM20: Permanent | AN20: Suivi réalisé vs budget EBITDA | AO20: 1 | AP20: - | AQ20: Mensuelle | AR20: Situations mensuelles | AS20: 0.12 | AT20: 0.17 | AU20: 0.23 | AV20: 0.28 | AW20: 0.42 | AX20: 0.55 | AY20: 0.63 | AZ20: 0.73 | BA20: 0.82 | BB20: 0.96 | BC20: 0.98 | BD20: 1.15 | BE20: 1.15 | BF20: 1 | BG20: 1
D21: 1 | E21: PR1 | F21: Contractualiser au maximum afin de minimiser le risque | G21: * | H21: AE | I21: Permanent | J21: Suivi du taux de contractualisation | K21: 0.71 | L21: Mensuelle | M21: Tableaux de facturation (cumul) | N21: 0.51155629 | O21: 0.51155629 | Z21: =IFERROR(LOOKUP(9^9,N21:Y21),0) -> 0.51155629 | AH21: 1 | AI21: PM1 | AJ21: Contractualiser au maximum afin de minimiser le risque | AK21: * | AL21: AE | AM21: Permanent | AN21: Suivi du taux de contractualisation | AO21: 0.71 | AP21: - | AQ21: Mensuelle | AR21: Tableaux de facturation (cumul) | AS21: 0.52 | AT21: 0.57 | AU21: 0.62 | AV21: 0.58 | AW21: 0.61 | AX21: 0.62 | AY21: 0.63 | AZ21: 0.63050545 | BA21: 0.62 | BB21: 0.62 | BC21: 0.59 | BD21: 0.59 | BE21: 0.59 | BF21: 0.71 | BG21: 0
D22: 3, 4 | E22: PR1 | F22: Diversifier le portefeuille client | G22: 1444 | H22: AE | I22: Permanent | J22: Nouvelles affaires (dossier validé) | K22: 13 | L22: Mensuelle | M22: "Y:\PM1 - Manager le systéme qualité\5 - Enregistrements\Registre de numérotation dossiers et documents\2024_Registre numérotation DOSSIERS COURRIERS.xls" - Onglet manquant | N22: 1 | O22: 0 | P22: 0 | Z22: =SUM(N22:Y22) -> 1 | AH22: 3, 4 | AI22: PR1 | AJ22: Diversifier le portefeuille client | AK22: 1444 | AL22: AE | AM22: Permanent | AN22: Nouvelles affaires (dossier validé) | AO22: 12 | AP22: - | AQ22: Mensuelle | AR22: "Y:\PM1 - Manager le systéme qualité\5 - Enregistrements\Registre de numérotation dossiers et documents\2024_Registre numérotation DOSSIERS COURRIERS.xls" - Onglet manquant | AS22: 1 | AT22: 1 | AU22: 0 | AV22: 2 | AW22: 0 | AX22: 1 | AY22: 0 | AZ22: 2 | BA22: 4 | BB22: 0 | BC22: 1 | BD22: 1 | BE22: 13 | BF22: 13 | BG22: 1
D23: 2 | E23: PR1 | F23: Maintenir l'activité existante | G23: 1444 | H23: AE | I23: Permanent | J23: Affaires perdues | K23: 0 | L23: Mensuelle | M23: "Y:\PM1 - Manager le systéme qualité\5 - Enregistrements\Registre de numérotation dossiers et documents\2024_Registre numérotation DOSSIERS COURRIERS.xls" - Onglet manquant | N23: 5 | O23: 0 | P23: 1 | Z23: =SUM(N23:Y23) -> 6 | AH23: 2 | AI23: PR1 | AJ23: Maintenir l'activité existante | AK23: 1444 | AL23: AE | AM23: Permanent | AN23: Affaires perdues | AO23: 0 | AP23: + | AQ23: Mensuelle | AR23: "Y:\PM1 - Manager le systéme qualité\5 - Enregistrements\Registre de numérotation dossiers et documents\2024_Registre numérotation DOSSIERS COURRIERS.xls" - Onglet manquant | AS23: 0 | AT23: 0 | AU23: 2 | AV23: 0 | AW23: 4 | AX23: 0 | AY23: 0 | AZ23: 0 | BA23: 0 | BB23: 0 | BC23: 0 | BD23: 0 | BE23: 6 | BF23: 0 | BG23: 0
AP24: -
AP25: -
A26: 2 | B26: Satisfaire nos parties prenantes et parties intéréssées | C26: O4 - Répondre aux exigences | D26: 1 | E26: PM1 | F26: Mesurer la perception de la satisfaction client | G26: 1444 | H26: AE | I26: 45930 | J26: Nombre d'enquêtes | K26: 2 | L26: Semestrielle | M26: Fichier d'étude de la perception | N26: - | O26: - | P26: - | Q26: - | S26: - | T26: - | U26: - | V26: - | W26: - | Y26: - | Z26: =SUM(N26:Y26) -> 0 | AE26: 2 | AF26: Satisfaire nos clients | AG26: O4 - Répondre aux exigences clients | AH26: 1 | AI26: PM1 | AJ26: Mesurer la perception de la satisfaction client | AK26: 1444 | AL26: AE | AM26: 45930 | AN26: Nombre d'enquêtes | AO26: 2 | AP26: - | AQ26: Semestrielle | AR26: Fichier d'étude de la perception | AS26: - | AT26: - | AU26: - | AV26: - | AW26: 1 | AX26: - | AY26: - | AZ26: - | BA26: - | BB26: - | BC26: 1 | BD26: - | BE26: 2 | BF26: 2 | BG26: 1
D27: 1 | E27: PM1 | F27: Se conformer aux exigences de nos partenaires | G27: Cf REC | H27: AE | I27: Permanent | J27: Nombre de réclamations | K27: 0 | L27: Mensuelle | M27: Suivi REC- pilotage activité | N27: 0 | O27: 0 | P27: 0 | Z27: =SUM(N27:Y27) -> 0 | AH27: 1 | AI27: PM1 | AJ27: Se conformer aux exigences de nos partenaires | AK27: Cf REC | AL27: AE | AM27: Permanent | AN27: Nombre de réclamations | AO27: 0 | AP27: + | AQ27: Mensuelle | AR27: Suivi REC- pilotage activité | AS27: 0 | AT27: 1 | AU27: 0 | AV27: 0 | AW27: 0 | AX27: 0 | AY27: 0 | AZ27: 0 | BA27: 0 | BB27: 0 | BC27: 0 | BD27: 0 | BE27: 1 | BF27: 0 | BG27: 0
D28: 1 | E28: PM1 | F28: Examiner les non-conformités et mettre en place les actions nécessaires | G28: Cf NC | H28: AE | I28: Permanent | J28: Nombre de non-conformités | K28: 0 | L28: Mensuelle | M28: Suivi NC - pilotage activité | N28: 0 | O28: 0 | P28: 0 | Z28: =SUM(N28:Y28) -> 0 | AH28: 1 | AI28: PM1 | AJ28: Examiner les non-conformités et mettre en place les actions nécessaires | AK28: Cf NC | AL28: AE | AM28: Permanent | AN28: Nombre de non-conformités | AO28: 0 | AP28: + | AQ28: Mensuelle | AR28: Suivi NC - pilotage activité | AS28: 0 | AT28: 0 | AU28: 0 | AV28: 0 | AW28: 0 | AX28: 0 | AY28: 0 | AZ28: 0 | BA28: 0 | BB28: 0 | BC28: 0 | BD28: 2 | BE28: 2 | BF28: 0 | BG28: 0
C29: O5 - Maitriser la qualité du service délivré | D29: 1, 2 | E29: PR2 | F29: Garantir la qualité de la prestation promise | G29: 1444 | H29: MR | I29: Permanent | J29: Taux de service | K29: 0.94 | L29: Mensuelle | M29: Fichier de suivi dans processus PR2 | N29: 0.913 | O29: 0.922 | P29: 0.952 | Z29: =IFERROR(LOOKUP(9^9,N29:Y29),0) -> 0.952 | AG29: O5 - Maitriser la qualité du service délivré | AH29: 1, 2 | AI29: PR2 | AJ29: Garantir la qualité de la prestation promise | AK29: 1444 | AL29: MR | AM29: Permanent | AN29: Taux de service | AO29: 0.94 | AP29: - | AQ29: Mensuelle | AR29: Fichier de suivi dans processus PR2 | AS29: 0.896 | AT29: 0.973 | AU29: 0.873 | AV29: 0.938 | AW29: 0.956 | AX29: 0.962 | AY29: 0.93 | AZ29: 0.961 | BA29: 0.899 | BB29: 0.892 | BC29: 0.96 | BD29: 0.876 | BE29: 0.876 | BF29: 0.94 | BG29: 0
D30: 1, 2 | E30: PR2 | F30: Garantir la qualité de la prestation promise | G30: 1444 | H30: MR | I30: Permanent | J30: "Programmation non prise en compte" 313 | K30: 0 | L30: Mensuelle | M30: Fichier de suivi dans processus PR2 | N30: 3 | O30: 0 | P30: 0 | Z30: =SUM(N30:Y30) -> 3 | AH30: 1, 2 | AI30: PR2 | AJ30: Garantir la qualité de la prestation promise | AK30: 1444 | AL30: MR | AM30: Permanent | AN30: "Programmation non prise en compte" 313 | AO30: 0 | AP30: + | AQ30: Mensuelle | AR30: Fichier de suivi dans processus PR2 | AS30: 0 | AT30: 1 | AU30: 3 | AV30: 0 | AW30: 2 | AX30: 4 | AY30: 1 | AZ30: 1 | BA30: 1 | BB30: 3 | BC30: 1 | BD30: 3 | BE30: 20 | BF30: 0 | BG30: 0
D31: 1, 2, 11 | E31: PR2 | F31: Garantir la qualité de la prestation promise | G31: 1444 | H31: MR | I31: Permanent | J31: Nombre de transporteurs présentant taux anomalie >5% 2 mois d'affilée - Modif Indicateur à pondérer | K31: 0 | L31: Mensuelle | M31: Fichier de suivi dans processus PR2 | Z31: =SUM(N31:Y31) -> 0 | AH31: 1, 2, 11 | AI31: PR2 | AJ31: Garantir la qualité de la prestation promise | AK31: 1444 | AL31: MR | AM31: Permanent | AN31: Nombre de transporteurs présentant taux anomalie >5% 2 mois d'affilée - Modif Indicateur à pondérer | AO31: 0 | AP31: + | AQ31: Mensuelle | AR31: Fichier de suivi dans processus PR2 | AS31: 0 | AT31: 0 | AU31: 0 | AV31: 0 | AW31: 0 | AX31: 0 | AY31: 0 | AZ31: 0 | BA31: 2 | BB31: 4 | BC31: 2 | BD31: 2 | BE31: 10 | BF31: 0 | BG31: 0
D32: 7 | E32: PR2 | F32: Garantir la qualité de la prestation promise | G32: 1454 | H32: MR | I32: Permanent | J32: Part des flux sous Dashdoc | K32: 1 | L32: Mensuelle | M32: Déclaratif | N32: 0.01 | O32: 0.02 | P32: 0.02 | AH32: 7 | AI32: PR2 | AJ32: Garantir la qualité de la prestation promise | AK32: 1454 | AL32: MR | AM32: Permanent | AN32: Part des flux sous Dashdoc | BF32: 1
D33: 1, 2 | E33: PR2 | F33: Avoir 2 transporteurs / flux (sauf cas justifiés) | G33: * | H33: MR | I33: Permanent | J33: Part des points de chargements disposant de 2 transporteurs | K33: 1 | L33: Mensuelle | M33: Données à date consignes affretement | N33: 0.96 | O33: 0.96 | P33: 0.96 | Z33: =IFERROR(LOOKUP(9^9,N33:Y33),0) -> 0.96 | AH33: 1, 2 | AI33: PR2 | AJ33: Avoir 2 transporteurs / flux (sauf cas justifiés) | AK33: * | AL33: MR | AM33: Permanent | AN33: Part des points de chargements disposant de 2 transporteurs | AO33: 1 | AP33: - | AQ33: Mensuelle | AR33: Données à date consignes affretement | AS33: 0.2 | AT33: 0.2 | AU33: 0.2 | AV33: 0.96 | AW33: 0.96 | AX33: 0.96 | AY33: 0.96 | AZ33: 0.96 | BA33: 0.96 | BB33: 0.96 | BC33: 0.96 | BD33: 0.96 | BE33: 0.96 | BF33: 1 | BG33: 0
D34: 1, 2 | E34: PS3 | F34: Evaluer les prestataires | G34: * | H34: RD | I34: Permanent | J34: Part des prestataires évalués ayant signé la charte éco responsable | K34: 1 | L34: Mensuelle | M34: "Y:\PS3 - Gérer les achats de biens et services\6 - Enregistrements\Engagement fournisseurs - charte eco responsable signée\2025_09 Liste fournisseurs et prestataires évalués en 092025.xlsx" | N34: 0.86 | O34: 0.95 | AH34: 1, 2 | AI34: PS3 | AJ34: Evaluer les prestataires | AK34: * | AL34: RD | AM34: Permanent | AN34: Part des prestataires évalués ayant signé la charte | BF34: 1
D35: 1, 2 | E35: PS3 | F35: Evaluer les prestataires | G35: 1444 | H35: RD | I35: 45930 | J35: Nombre de prestataires insatisfaisant | K35: 0 | L35: Annuelle | M35: Enquête satisfaction prestataire | Y35: 0 | Z35: =Y35 -> 0 | AH35: 1, 2 | AI35: PS3 | AJ35: Evaluer les prestataires | AK35: 1444 | AL35: RD | AM35: 45930 | AN35: Nombre de prestataires insatisfaisant | AO35: 0 | AP35: + | AQ35: Annuelle | AR35: Enquête satisfaction prestataire | BD35: 0 | BE35: 0 | BF35: 0 | BG35: 1
A38: ENVIRONNEMENT | AE38: ENVIRONNEMENT
A39: 4 | B39: Intégrer les enjeux environnementaux et climatiques comme facteur stratégique de compétitivité et d’innovation | C39: O6 - Offrir une gamme de service plus étoffée | D39: 3 | E39: PR1 | F39: Réduire la mise en décharge | G39: 1444 | H39: AE | I39: Permanent | J39: Taux de valorisation | K39: 0.96 | L39: Mensuelle | M39: TDF (cumul) | N39: 0.9653623 | O39: 0.93932957 | Z39: =IFERROR(LOOKUP(9^9,N39:Y39),0) -> 0.93932957 | AE39: 4 | AF39: Intégrer les enjeux environnementaux et climatiques comme facteur stratégique de compétitivité et d’innovation | AG39: O6 - Offrir une gamme de service plus étoffée à nos clients | AH39: 3 | AI39: PR1 | AJ39: Réduire la mise en décharge | AK39: 1444 | AL39: AE | AM39: Permanent | AN39: Taux de valorisation | AO39: 0.93 | AP39: - | AQ39: Mensuelle | AR39: TDF (cumul) | AS39: 0.91 | AT39: 0.91338691 | AU39: 0.92 | AV39: 0.94944168 | AW39: 0.95724277 | AX39: 0.9594591 | AY39: 0.95930104 | AZ39: 0.95982949 | BA39: 0.95805717 | BB39: 0.95805717 | BC39: 0.95586837 | BD39: 0.95586837 | BE39: 0.95586837 | BF39: 0.96 | BG39: 1
D40: 3 | E40: PR1 | F40: Réduire la mise en décharge | G40: 1444 | H40: AE | I40: Permanent | J40: Taux de valorisation (yc remblais) | K40: 0.98 | L40: Mensuelle | M40: TDF (cumul) | N40: 0.991774 | O40: 0.96882372 | Z40: =IFERROR(LOOKUP(9^9,N40:Y40),0) -> 0.96882372 | AH40: 3 | AI40: PR1 | AJ40: Réduire la mise en décharge | AK40: 1444 | AL40: AE | AM40: Permanent | AN40: Taux de valorisation (yc remblais) | AO40: 0.96 | AP40: - | AQ40: Mensuelle | AR40: TDF (cumul) | AS40: 0.9412 | AT40: 0.94123779 | AU40: 0.95 | AV40: 0.97224026 | AW40: 0.9782291 | AX40: 0.97888613 | AY40: 0.97929936 | AZ40: 0.97884513 | BA40: 0.97972117 | BB40: 0.97972117 | BC40: 0.98036109 | BD40: 0.98036109 | BE40: 0.98036109 | BF40: 0.98 | BG40: 1
D41: 8 | E41: PR2 | F41: Mesurer l'impact CO2 lié à notre activité | G41: * | H41: MR | I41: Permanent | J41: Kgs CO2 / Tonne traitée | K41: BC | L41: Mensuelle | M41: A date AU CUMUL | Z41: =IFERROR(LOOKUP(9^9,N41:Y41),0) -> 0 | AH41: 8 | AI41: PR2 | AJ41: Mesurer l'impact CO2 lié à notre activité | AK41: * | AL41: MR | AM41: Permanent | AN41: Kgs CO2 / Tonne traitée | AO41: 14.954524 | AP41: + | AQ41: Mensuelle | AR41: A date AU CUMUL | AS41: 27.910603 | AT41: 32.486019 | AU41: 27.291221 | AV41: 34.130678 | AW41: 30.501514 | AX41: 33.041847 | AY41: 20.564174 | AZ41: 19.972238 | BA41: 27.518844 | BB41: 27.071737 | BC41: 32.35 | BD41: 26.8 | BE41: 26.8 | BF41: BC | BG41: 0
D42: 8 | E42: PR2 | F42: Mesurer l'impact CO2 lié à notre activité | G42: * | H42: MR | I42: Permanent | J42: Emissions Tonnes CO2 | K42: BC | L42: Mensuelle | M42: A date AU CUMUL | N42: 233.78 | O42: 142.4 | P42: 121.35 | Z42: =SUM(N42:Y42) -> 497.53 | AH42: 8 | AI42: PR2 | AJ42: Mesurer l'impact CO2 lié à notre activité | AK42: * | AL42: MR | AM42: Permanent | AN42: Emissions Tonnes CO2 | AO42: 1626 | AP42: + | AQ42: Mensuelle | AR42: A date AU CUMUL | AS42: 221.83295 | AT42: 161.82845 | AU42: 92.045919 | AV42: 170.18052 | AW42: 245.18985 | AX42: 255.73885 | AY42: 178.44535 | AZ42: 163.55415 | BA42: 230.50053 | BB42: 190.61638 | BC42: 62 | BD42: 180 | BE42: 2151.933 | BF42: BC | BG42: 0
C43: O1 -Améliorer l'organisation interne | D43: 14 | E43: PS2 | F43: Recycler les déchets générés par les bureaux | G43: * | H43: RD | I43: Permanent | J43: Qté de déchets traités par ELISE | K43: 49 | L43: Mensuelle | M43: Facture Elise | N43: ='ENV_Suivi déchets'!I7 -> 0 | O43: ='ENV_Suivi déchets'!I8 -> 0 | P43: ='ENV_Suivi déchets'!I9 -> 0 | Q43: ='ENV_Suivi déchets'!I10 -> 0 | R43: ='ENV_Suivi déchets'!I11 -> 0 | S43: ='ENV_Suivi déchets'!I12 -> 0 | T43: ='ENV_Suivi déchets'!I13 -> 0 | U43: ='ENV_Suivi déchets'!I14 -> 0 | V43: ='ENV_Suivi déchets'!I15 -> 0 | W43: ='ENV_Suivi déchets'!I16 -> 0 | X43: ='ENV_Suivi déchets'!I17 -> 0 | Y43: ='ENV_Suivi déchets'!I18 -> 0 | Z43: =SUM(N43:Y43) -> 0 | AG43: O1 -Améliorer l'organisation interne | AH43: 14 | AI43: PM1 | AJ43: Recycler les déchets générés par les bureaux d'ABO France | AK43: * | AL43: RD | AM43: Permanent | AN43: Volume de déchets traités par ELISE | AO43: Max | AP43: + | AQ43: Mensuelle | AR43: Facture Elise | AS43: 0 | AT43: 0 | AU43: 0 | AV43: 0 | AW43: 0 | AX43: 0 | AY43: 0 | AZ43: 23.5 | BA43: 0 | BB43: 0 | BC43: 0 | BD43: 25 | BE43: 48.5 | BF43: 49 | BG43: 1
...

Sheet ENV_Suivi électricité
B1: SUIVI DES CONSOMMATIONS D'ELECTRICITE
B5: SUIVI CONSOMMATION EDF EN KWH
C7: 17-18 | D7: 18-19 | E7: 19-20 | F7: 20-21 | G7: 21-22 | H7: 22-23 | I7: 23-24 | J7: 24-25 | K7: 25-26
B8: octobre | D8: 206 | E8: 245 | F8: 204 | G8: 189 | H8: 276 | I8: 155 | J8: 280 | K8: 324
B9: novembre | D9: 216 | E9: 248 | F9: 205 | G9: 177 | H9: 249 | I9: 161 | J9: 235 | K9: 206
B10: décembre | D10: 214 | E10: 232 | F10: 181 | G10: 201 | H10: 268 | I10: 185 | J10: 179
B11: janvier | C11: 239 | D11: 207 | E11: 222 | F11: 190 | G11: 194 | H11: 276 | I11: 162 | J11: 158
B12: février | C12: 239 | D12: 234 | E12: 232 | F12: 199 | G12: 206 | H12: 260 | I12: 185 | J12: 180
B13: mars | C13: 205 | D13: 381 | E13: 204 | F13: 203 | G13: 180 | H13: 149 | I13: 161 | J13: 193
B14: avril | C14: 224 | D14: 59 | E14: 197 | F14: 226 | G14: =169+82 -> 251 | H14: 169 | I14: 168 | J14: 203
B15: mai | C15: 198 | D15: 219 | E15: 166 | F15: 193 | G15: 237 | H15: 138 | I15: 146 | J15: 189
B16: juin | C16: 215 | D16: 206 | E16: 182 | F16: 182 | G16: 246 | H16: 165 | I16: 177 | J16: 199
B17: juillet | C17: 212 | D17: 201 | E17: 205 | F17: 334 | G17: 246 | H17: 155 | I17: 162 | J17: 189
B18: août | C18: 213 | D18: 241 | E18: 205 | F18: 55 | G18: 246 | H18: 148 | I18: 175 | J18: 193
B19: septembre | C19: 208 | D19: 235 | E19: 206 | F19: 197 | G19: 264 | H19: 141 | I19: 180 | J19: 204
B20: Total Kw/h | C20: =SUM(C8:C19) -> 1953 | D20: =SUM(D8:D19) -> 2619 | E20: =SUM(E8:E19) -> 2544 | F20: =SUM(F8:F19) -> 2369 | G20: =SUM(G8:G19) -> 2637 | H20: =SUM(H8:H19) -> 2394 | I20: =SUM(I8:I19) -> 2017 | J20: =SUM(J8:J19) -> 2402 | K20: =SUM(K8:K19) -> 530
B21: moyenne mensuelle | C21: =+C20/9 -> 217 | D21: =+D20/12 -> 218.25 | E21: =+E20/12 -> 212 | F21: =+F20/12 -> 197.41667 | G21: =+G20/12 -> 219.75 | H21: =+H20/COUNTA(H8:H19) -> 199.5 | I21: =+I20/COUNTA(I8:I19) -> 168.08333 | J21: =+J20/COUNTA(J8:J19) -> 200.16667 | K21: =+K20/COUNTA(K8:K19) -> 265
B22: Jours ouvrés | C22: =20*9 -> 180 | D22: 251 | E22: 253 | F22: 254 | G22: 254 | H22: 251 | I22: 252 | J22: 254 | K22: 259
B23: moyenne JO | C23: =+C20/C22 -> 10.85 | D23: =+D20/D22 -> 10.434263 | E23: =+E20/E22 -> 10.055336 | F23: =+F20/F22 -> 9.3267717 | G23: =+G20/G22 -> 10.38189 | H23: =+H20/H22 -> 9.5378486 | I23: =+I20/I22 -> 8.0039683 | J23: =+J20/J22 -> 9.4566929 | K23: =+K20/K22 -> 2.046332
B24: Par personne | C24: =+C21/3 -> 72.333333 | D24: =+D21/3 -> 72.75 | E24: =+E21/3 -> 70.666667 | F24: =+F21/2 -> 98.708333 | G24: =+G21/3 -> 73.25 | H24: =H21/2.5 -> 79.8 | I24: =I21/4 -> 42.020833 | J24: =J21/4 -> 50.041667 | K24: =K21/4 -> 66.25
B26: 32 Boulevard Ferdinand de Lesseps

Sheet ENV_Suivi déchets
B1: SUIVI DES DECHETS ABO France ENLEVES ET TRAITES PAR ELISE
K2: Coût des équipements de base : 257,50 € (26/02/2025)
B6: Exercice 25-26 | C6: Papier / Carton | D6: D3E | E6: Cartouches | F6: Capsules | G6: Canettes | H6: Plastique | I6: Total kgs | J6: Coût HT | K6: Coût / kg
B7: octobre (06/10/2025)
B8: novembre
B9: décembre
B10: janvier
B11: février
B12: mars
B13: avril
B14: mai
B15: juin
B16: juillet
B17: août
B18: septembre
B19: Total KGS | C19: =SUM(C10:C18) -> 0 | D19: =SUM(D10:D18) -> 0 | E19: =SUM(E10:E18) -> 0 | F19: =SUM(F10:F18) -> 0 | G19: =SUM(G10:G18) -> 0 | H19: =SUM(H10:H18) -> 0 | I19: =SUM(C19:H19) -> 0 | J19: =SUM(J10:J18) -> 0 | K19: =IFERROR(J19/I19,0) -> 0
B26: Exercice 24-25 | C26: Papier / Carton | D26: D3E | E26: Cartouches | F26: Capsules | G26: Canettes | H26: Plastique | I26: Total kgs | J26: Coût HT | K26: Coût / kg
B27: octobre | I27: =SUM(C27:H27) -> 0
B28: novembre | I28: =SUM(C28:H28) -> 0
B29: décembre | I29: =SUM(C29:H29) -> 0
B30: janvier | C30: 0 | D30: 0 | E30: 0 | F30: 0 | G30: 0 | H30: 0 | I30: =SUM(C30:H30) -> 0 | J30: 0
B31: février | C31: 0 | D31: 0 | E31: 0 | F31: 0 | G31: 0 | H31: 0 | I31: =SUM(C31:H31) -> 0 | J31: 0
B32: mars | C32: 0 | D32: 0 | E32: 0 | F32: 0 | G32: 0 | H32: 0 | I32: =SUM(C32:H32) -> 0 | J32: 0
B33: avril | C33: 0 | D33: 0 | E33: 0 | F33: 0 | G33: 0 | H33: 0 | I33: =SUM(C33:H33) -> 0 | J33: 0
B34: mai (20/05/2025) | C34: 17 | D34: 1 | E34: 1 | F34: 2.5 | G34: 1 | H34: 1 | I34: =SUM(C34:H34) -> 23.5 | J34: 96.35 | K34: =J34/I34 -> 4.1
B35: juin | I35: =SUM(C35:H35) -> 0
B36: juillet | I36: =SUM(C36:H36) -> 0
B37: août | I37: =SUM(C37:H37) -> 0
B38: septembre | C38: 13 | F38: 9 | G38: 1 | H38: 1 | I38: 24 | J38: 46.35 | K38: 1.93125
B39: Total KGS | C39: =SUM(C30:C38) -> 30 | D39: =SUM(D30:D38) -> 1 | E39: =SUM(E30:E38) -> 1 | F39: =SUM(F30:F38) -> 11.5 | G39: =SUM(G30:G38) -> 2 | H39: =SUM(H30:H38) -> 2 | I39: =SUM(C39:H39) -> 47.5 | J39: =SUM(J30:J38) -> 142.7 | K39: =J39/I39 -> 3.0042105

Sheet ENV_Suivi copies
B1: SUIVI DES CONSOMMATIONS D'IMPRESSION PAPIER
C9: Consommations copies couleur | G9: Consommations copies NB | K9: Conso
C10: Compteur départ | D10: Compteur arrivée | E10: Consommation totale | G10: Compteur départ | H10: Compteur arrivée | I10: Consommation totale | K10: Total cumul
B11: 23/09 - 20/12/2021 | E11: =IF((D11-C11)<0,0,(D11-C11)) -> 0 | I11: =IF((H11-G11)<0,0,(H11-G11)) -> 0 | K11: =I11+E11 -> 0
B12: 20/12/21 - 28/03/2022 | C12: =D11 -> 0 | E12: =IF((D12-C12)<0,0,(D12-C12)) -> 0 | G12: =H11 -> 0 | I12: =IF((H12-G12)<0,0,(H12-G12)) -> 0 | K12: =I12+E12 -> 0
B13: 28/03 - 01/06/2022 | C13: =D12 -> 0 | E13: =IF((D13-C13)<0,0,(D13-C13)) -> 0 | G13: =H12 -> 0 | I13: =IF((H13-G13)<0,0,(H13-G13)) -> 0 | K13: =I13+E13 -> 0
B14: 01/06 - 12/09/2022 | C14: =D13 -> 0 | E14: =IF((D14-C14)<0,0,(D14-C14)) -> 0 | G14: =H13 -> 0 | I14: =IF((H14-G14)<0,0,(H14-G14)) -> 0 | K14: =I14+E14 -> 0
B15: 45923 | C15: =D14 -> 0 | D15: 482 | E15: =IF((D15-C15)<0,0,(D15-C15)) -> 482 | G15: =H14 -> 0 | H15: 193 | I15: =IF((H15-G15)<0,0,(H15-G15)) -> 193 | K15: =I15+E15 -> 675
B16: 44916 | C16: =D15 -> 482 | D16: 4834 | E16: =IF((D16-C16)<0,0,(D16-C16)) -> 4352 | G16: =H15 -> 193 | H16: 1534 | I16: =IF((H16-G16)<0,0,(H16-G16)) -> 1341 | K16: =I16+E16 -> 5693
B17: 31/12/22 - 30/03/2023 | C17: =D16 -> 4834 | D17: 10015 | E17: =IF((D17-C17)<0,0,(D17-C17)) -> 5181 | G17: =H16 -> 1534 | H17: 2688 | I17: =IF((H17-G17)<0,0,(H17-G17)) -> 1154 | K17: =I17+E17 -> 6335
B18: 31/03 - 29/06/2023 | C18: =D17 -> 10015 | D18: 13650 | E18: =IF((D18-C18)<0,0,(D18-C18)) -> 3635 | G18: =H17 -> 2688 | H18: 3400 | I18: =IF((H18-G18)<0,0,(H18-G18)) -> 712 | K18: =I18+E18 -> 4347
B19: 30/06 - 29/09/2023 | C19: =D18 -> 13650 | D19: 17196 | E19: =IF((D19-C19)<0,0,(D19-C19)) -> 3546 | G19: =H18 -> 3400 | H19: 4039 | I19: =IF((H19-G19)<0,0,(H19-G19)) -> 639 | K19: =I19+E19 -> 4185
A20: Exercice | B20: 30/09/2023 - 03/01/2024 | C20: =D19 -> 17196 | D20: 22052 | E20: =IF((D20-C20)<0,0,(D20-C20)) -> 4856 | G20: =H19 -> 4039 | H20: 5112 | I20: =IF((H20-G20)<0,0,(H20-G20)) -> 1073 | K20: =I20+E20 -> 5929
A21: 23-24 | B21: 04/01/2024 - 08/04/2024 | C21: =D20 -> 22052 | D21: 25806 | E21: =IF((D21-C21)<0,0,(D21-C21)) -> 3754 | G21: =H20 -> 5112 | H21: 5354 | I21: =IF((H21-G21)<0,0,(H21-G21)) -> 242 | K21: =I21+E21+K20 -> 9925
B22: 09/04/2024 - 01/07/2024 | C22: =D21 -> 25806 | D22: 29226 | E22: =IF((D22-C22)<0,0,(D22-C22)) -> 3420 | G22: =H21 -> 5354 | H22: 5865 | I22: =IF((H22-G22)<0,0,(H22-G22)) -> 511 | K22: =I22+E22+K21 -> 13856
B23: 02/07/2024 - 19/09/2024 | C23: =D22 -> 29226 | D23: 29384 | E23: =IF((D23-C23)<0,0,(D23-C23)) -> 158 | G23: =H22 -> 5865 | H23: 12057 | I23: =IF((H23-G23)<0,0,(H23-G23)) -> 6192 | K23: =I23+E23+K22 -> 20206
A25: Exercice | B25: 20/09/2024 - 24/12/2024 | C25: =D23 -> 29384 | D25: 31487 | E25: =IF((D25-C25)<0,0,(D25-C25)) -> 2103 | G25: =H23 -> 12057 | H25: 15208 | I25: =IF((H25-G25)<0,0,(H25-G25)) -> 3151 | K25: =I25+E25 -> 5254
A26: 24-25 | B26: 25/12/2024 - 24/03/2025 | C26: =D25 -> 31487 | D26: 32808 | E26: =IF((D26-C26)<0,0,(D26-C26)) -> 1321 | G26: =H25 -> 15208 | H26: 18324 | I26: =IF((H26-G26)<0,0,(H26-G26)) -> 3116 | K26: =I26+E26+K25 -> 9691
B27: 25/03/2025 - 29/06/2025 | C27: =D26 -> 32808 | D27: 33404 | E27: =IF((D27-C27)<0,0,(D27-C27)) -> 596 | G27: =H26 -> 18324 | H27: 22106 | I27: =IF((H27-G27)<0,0,(H27-G27)) -> 3782 | K27: =I27+E27+K26 -> 14069
B28: 30/06/2025 - 29/09/2025 | C28: =D27 -> 33404 | D28: 34058 | E28: =IF((D28-C28)<0,0,(D28-C28)) -> 654 | G28: =H27 -> 22106 | H28: 25823 | I28: =IF((H28-G28)<0,0,(H28-G28)) -> 3717 | K28: =I28+E28+K27 -> 18440 | L28: =(K28-K23)/K23 -> -0.087399782
A30: Exercice | B30: 01/10/2025 - 31/12/2025 | C30: =D28 -> 34058 | E30: =IF((D30-C30)<0,0,(D30-C30)) -> 0 | G30: =H28 -> 25823 | I30: =IF((H30-G30)<0,0,(H30-G30)) -> 0 | K30: =I30+E30 -> 0
A31: 25-26 | E31: =IF((D31-C31)<0,0,(D31-C31)) -> 0 | I31: =IF((H31-G31)<0,0,(H31-G31)) -> 0 | K31: =I31+E31+K30 -> 0
E32: =IF((D32-C32)<0,0,(D32-C32)) -> 0 | I32: =IF((H32-G32)<0,0,(H32-G32)) -> 0 | K32: =I32+E32+K31 -> 0
E33: =IF((D33-C33)<0,0,(D33-C33)) -> 0 | I33: =IF((H33-G33)<0,0,(H33-G33)) -> 0 | K33: =I33+E33+K32 -> 0 | L33: =(K33-K28)/K28 -> -1
K35: Objectif : réduction de 5% en 25-26 vs 24-25

Sheet ENV_Analyse Env
B1: ANALYSE ENVIRONNEMENTALE
A6: Date de mise à jour : 12/02/2025 | F6: Cotation du Risque Initial (RI)
A7: Aspect | B7: Sous aspect environnementaux | C7: Cause de l'impact | D7: Impact environnemental | E7: Mode | F7: Probabilité | G7: Fréquence | H7: Gravité | I7: Total RI | J7: Actions pour réduire l'impact | K7: Maîtrise | L7: ICPE | M7: Risque résiduel | N7: 🙂
A8: Air | B8: Odeurs | C8: Odeurs liées à certains produits chimiques si utilisés dans un local fermé (erreur humaine ou locaux du client inadaptés) | D8: Pollution olfactive Risque pour la santé humaine | E8: A | F8: 2 | G8: 2 | H8: 2 | I8: =+F8*G8*H8 -> 8 | J8: Formation du personnel EPI à disposition Plans de Prévention (coactivité) | K8: 0.01 | M8: =+IFERROR(I6*K6,0) -> 0 | N8: 😀
A9: Energie | B9: Air | C9: Emmision de CO2 | D9: polution de l'air Diminution des ressources naturelles | E9: A | F9: 2 | G9: 2 | H9: 3 | I9: =+F9*G9*H9 -> 12 | J9: Utilisation des Transports en Communs pour x % des salariés Réalisation de Bilan Carbone Achats de véhicules Hybrides / electrique Maintenance flotte automobile | M9: =+IFERROR(I7*K7,0) -> 0 | N9: 😀
A10: Air | B10: Air | C10: Déplacements des salariés (véhicules motorisés) | D10: Pollution de l'air Réchauffement climatique | E10: N | F10: 4 | G10: 2 | H10: 3 | I10: =+F10*G10*H10 -> 24 | J10: Utilisation des Transports en Communs pour x % des salariés Achats de véhicules Hybrides Formation Eco Conduite Organisation des déplacements | K10: 0.01 | M10: =+IFERROR(I8*K8,0) -> 0.08 | N10: 😀
A11: Déchets | B11: Déchets | C11: La production de déchets liés aux prestations (utilisation de consommables) collecte papier / cartons / DEEE / cartouche imprimantes | D11: Augmentation du volume des déchets (DIB) | E11: N | F11: 4 | G11: 4 | H11: 3 | I11: =+F11*G11*H11 -> 48 | J11: Tri des Déchets Formation du personnel aux éco-gestes Etude des besoins et limitation des consommables à usages unique Choix de matériel à longue durée de vie lorsque c'est possible | K11: 0.01 | M11: =+IFERROR(I9*K9,0) -> 0 | N11: 😀
A12: Déchets | B12: Déchets | C12: Le traitement des déchets liés aux prestations. La fin de vie des matériels traitée en enfouissement. | D12: Augmentation du volume des déchets (DIB) | E12: N | F12: 3 | G12: 3 | H12: 3 | I12: =+F12*G12*H12 -> 27 | J12: Tri des Déchets Formation du personnel aux éco-gestes Etude des besoins et limitation des consommables à usages unique Choix de matériel à longue durée de vie lorsque c'est possible | K12: 0.01 | M12: =+IFERROR(I10*K10,0) -> 0.24 | N12: 😀
A16: Grille de Cotation

Sheet SOC_Liste personnel
B1: SUIVI DU PERSONNEL
A6: GENERAL | M6: 24-25 | P6: 25-26
A7: Numéro | B7: Nom | C7: Nom marital | D7: Prénom | E7: Service | F7: Sexe | G7: Code CIPDZ | H7: CDD | I7: Handicapé | J7: Date d'entrée | K7: Date de sortie | L7: % activité | M7: Date entretien individuel | N7: Date entretien individuel milieu exercice | O7: Date entretien professionnel | P7: Date entretien individuel | Q7: Date entretien individuel milieu exercice | R7: Date entretien professionnel
A8: 16 | B8: ELUAU | D8: Axelle | E8: Direction | F8: Femme | G8: C | H8: Non | I8: Non | J8: 04/11/2019 | L8: 1 | M8: NA | N8: NA | O8: NA | P8: NA | Q8: NA | R8: NA
A9: 17 | B9: DOS SANTOS ROSA | D9: Théo | E9: Affrétement | F9: Homme | G9: P | H9: Oui | I9: Non | J9: 04/07/2022 | K9: 05/07/2024 | L9: 0.5
A10: 18 | B10: DUCHENE | D10: Renée | E10: Comptabilité | F10: Femme | G10: C | H10: Non | I10: Non | J10: 02/10/2023 | L10: 1 | M10: 45636 | N10: 45810 | O10: 46007 | P10: 46007 | R10: NA
A11: 19 | B11: MONGET | D11: Caroline | E11: Affrétement | F11: Femme | G11: C | H11: Non | I11: Non | J11: 08/01/2024 | L11: 1 | M11: 45628 | N11: 45821 | O11: NA | P11: 46008 | R11: 46008
A12: 20 | B12: RACHEDI | D12: Michel | E12: Affrétement | F12: Homme | G12: C | H12: Non | I12: Non | J12: 17/06/2024 | L12: 1 | M12: 45636 | N12: 45811 | O12: NA | P12: 46008

Sheet SOC_Abs
B1: Suivi du taux d'absentéisme - Exercice 25/06 | R1: Jours fériés | S1: Date
R2: Jour de l'an | S2: 45658
R3: Lundi de pâques | S3: 45768
R4: Fete du travail | S4: 45778
R5: Victoire alliés | S5: 45785
B6: =B7 -> 45931 | C6: =C7 -> 45962 | D6: =D7 -> 45992 | E6: =E7 -> 46023 | F6: =F7 -> 46054 | G6: =G7 -> 46082 | H6: =H7 -> 46113 | I6: =I7 -> 46143 | ... M6: =M7 -> 46266 | N6: Total | R6: Ascension | T6: 45437
A7: Date début mois | B7: 45931 | C7: 45962 | D7: 45992 | E7: 46023 | F7: 46054 | G7: 46082 | H7: 46113 | I7: 46143 | J7: 46174 | K7: 46204 | L7: 46235 | M7: 46266 | R7: Pentecote | S7: 45432
A8: Date fin mois | B8: 45961 | C8: 45991 | D8: 46022 | E8: 46053 | F8: 46081 | G8: 46112 | H8: 46142 | I8: 46173 | J8: 46203 | K8: 46234 | L8: 46265 | M8: 46295 | R8: Fete nationale | S8: 45487
A9: jours | B9: =DATEDIF(B7,B8,"d")+1 -> 31 | C9: =DATEDIF(C7,C8,"d")+1 -> 30 | D9: =DATEDIF(D7,D8,"d")+1 -> 31 | E9: =DATEDIF(E7,E8,"d")+1 -> 31 | F9: =DATEDIF(F7,F8,"d")+1 -> 28 | G9: =DATEDIF(G7,G8,"d")+1 -> 31 | H9: =DATEDIF(H7,H8,"d")+1 -> 30 | I9: =DATEDIF(I7,I8,"d")+1 -> 31 | ... M9: =DATEDIF(M7,M8,"d")+1 -> 30 | N9: =SUM(B9:M9) -> 365 | P9: Automatique
A10: jours ouvrés/travaillés | B10: =NETWORKDAYS(B7,B8,$S$2:$S$13) -> 23 | C10: =NETWORKDAYS(C7,C8,$S$2:$S$13) -> 19 | D10: =NETWORKDAYS(D7,D8,$S$2:$S$13) -> 22 | E10: =NETWORKDAYS(E7,E8,$S$2:$S$13) -> 22 | F10: =NETWORKDAYS(F7,F8,$S$2:$S$13) -> 20 | G10: =NETWORKDAYS(G7,G8,$S$2:$S$13) -> 22 | H10: =NETWORKDAYS(H7,H8,$S$2:$S$13) -> 22 | I10: =NETWORKDAYS(I7,I8,$S$2:$S$13) -> 21 | ... M10: =NETWORKDAYS(M7,M8,$S$2:$S$13) -> 22 | N10: =SUM(B10:M10) -> 259 | P10: Automatique | R10: Assomption | S10: 45884
A11: jours week end | B11: =B9-NETWORKDAYS(B7,B8) -> 8 | C11: =C9-NETWORKDAYS(C7,C8) -> 10 | D11: =D9-NETWORKDAYS(D7,D8) -> 8 | E11: =E9-NETWORKDAYS(E7,E8) -> 9 | F11: =F9-NETWORKDAYS(F7,F8) -> 8 | G11: =G9-NETWORKDAYS(G7,G8) -> 9 | H11: 8 | I11: =I9-NETWORKDAYS(I7,I8) -> 10 | J11: =J9-NETWORKDAYS(J7,J8) -> 8 | K11: =K9-NETWORKDAYS(K7,K8) -> 8 | L11: =L9-NETWORKDAYS(L7,L8) -> 10 | M11: =M9-NETWORKDAYS(M7,M8) -> 8 | N11: =SUM(B11:M11) -> 104 | P11: Automatique | R11: Toussaint | T11: 45962
A12: jours feriés hors w-e | B12: {=SUMPRODUCT(($S$2:$S$13>=B7)*($S$2:$S$13<=B8))} -> 0 | C12: =SUMPRODUCT(($S$2:$S$13>=C7)*($S$2:$S$13<=C8)) -> 1 | D12: =SUMPRODUCT(($S$2:$S$13>=D7)*($S$2:$S$13<=D8)) -> 1 | E12: =SUMPRODUCT(($S$2:$S$13>=E7)*($S$2:$S$13<=E8)) -> 0 | F12: =SUMPRODUCT(($S$2:$S$13>=F7)*($S$2:$S$13<=F8)) -> 0 | G12: =SUMPRODUCT(($S$2:$S$13>=G7)*($S$2:$S$13<=G8)) -> 0 | H12: =SUMPRODUCT(($S$2:$S$13>=H7)*($S$2:$S$13<=H8)) -> 0 | I12: =SUMPRODUCT(($S$2:$S$13>=I7)*($S$2:$S$13<=I8)) -> 0 | J12: =SUMPRODUCT(($S$2:$S$13>=J7)*($S$2:$S$13<=J8)) -> 0 | ... M12: =SUMPRODUCT(($S$2:$S$13>=M7)*($S$2:$S$13<=M8)) -> 0 | N12: =SUM(B12:M12) -> 2 | P12: Automatique | R12: Armistice | S12: 45972
R13: Noel | S13: 46016
A14: effectif annuel | N14: =IFERROR(AVERAGE(B14:M14),0) -> 0
A16: Nombre de jours d'absence
A17: Maladie | N17: =SUM(B17:M17) -> 0
A18: Formation | N18: =SUM(B18:M18) -> 0
A19: Accidents de travail | N19: =SUM(B19:M19) -> 0
A20: Chomage partiel | N20: =SUM(B20:M20) -> 0
A21: Total | B21: =SUM(B17:B20)-B18 -> 0 | C21: =SUM(C17:C20)-C18 -> 0 | D21: =SUM(D17:D20)-D18 -> 0 | E21: =SUM(E17:E20)-E18 -> 0 | F21: =SUM(F17:F20)-F18 -> 0 | G21: =SUM(G17:G20)-G18 -> 0 | H21: =SUM(H17:H20)-H18 -> 0 | I21: =SUM(I17:I20)-I18 -> 0 | ... M21: =SUM(M17:M20)-M18 -> 0 | N21: =SUM(B21:M21) -> 0
A23: Taux d'absentéisme | B23: =IFERROR((B21*100)/(B14*B10)/100,0) -> 0 | C23: =IFERROR((C21*100)/(C14*C10)/100,0) -> 0 | D23: =IFERROR((D21*100)/(D14*D10)/100,0) -> 0 | E23: =IFERROR((E21*100)/(E14*E10)/100,0) -> 0 | F23: =IFERROR((F21*100)/(F14*F10)/100,0) -> 0 | G23: =IFERROR((G21*100)/(G14*G10)/100,0) -> 0 | H23: =IFERROR((H21*100)/(H14*H10)/100,0) -> 0 | I23: =IFERROR((I21*100)/(I14*I10)/100,0) -> 0 | ... M23: =IFERROR((M21*100)/(M14*M10)/100,0) -> 0 | N23: =+IFERROR((N21*100)/(N14*N10)/100,0) -> 0
A24: Taux d'absentéisme en France | B24: 0.048 | C24: 0.048 | D24: 0.048 | E24: 0.048 | F24: 0.048 | G24: 0.048 | H24: 0.048 | I24: 0.048 | J24: 0.048 | K24: 0.048 | L24: 0.048 | M24: 0.048 | N24: 0.048
A25: Taux de fréquence | N25: =SUM(B25:M25) -> 0
A26: Taux de gravité | N26: =SUM(B26:M26) -> 0

Sheet SOC_PDF
B1: Plan de formation - Année 2025-2026
A6: PROCESSUS | B6: NOM DU STAGE | C6: COTATION | D6: ORGANISME | E6: STAGIAIRE | F6: PROVENANCE | G6: DATES PLANNIFIEES | H6: INSCRIPTION SITE OPCO | I6: DATE DE FIN | J6: RETOUR FORMALISE (PS1 F 004) | K6: REALISE | L6: DUREE (Heure) | M6: COUT DU STAGE (€ HT) | N6: COUT SALARIAL (€) | O6: FRAIS DE DEPLACMENTS (€) | P6: COUT TOTAL (€ HT) | Q6: MONTANT PRIS EN CHARGE PAR OPCO 2I (€ HT) | R6: OPCO REGLE L'ORGANISME DE FORMATION | S6: DATE REGLEMENT OPCO | T6: RESTE A CHARGE ABO FRANCE (€ HT)
A7: PM1 | B7: Sensibilisation cybersecurité - Médaille argent | C7: Niveau 1 | D7: Phished Academy | E7: Caroline MONGET | F7: Abo BE | G7: 45769 | K7: =IF(I7<>"",1,0) -> 0 | L7: 4 | M7: 0 | N7: 0 | O7: 0 | P7: =SUM(M7:O7) -> 0 | T7: =P7-Q7 -> 0
A8: PM1 | B8: Sensibilisation cybersecurité - Médaille argent | C8: Niveau 1 | D8: Phished Academy | E8: Michel RACHEDI | F8: Abo BE | G8: 45769 | K8: =IF(I8<>"",1,0) -> 0 | L8: 4 | M8: 0 | N8: 0 | O8: 0 | P8: =SUM(M8:O8) -> 0 | T8: =P8-Q8 -> 0
A9: PM1 | B9: Sensibilisation cybersecurité - Médaille argent | C9: Niveau 1 | D9: Phished Academy | E9: Renée DUCHENE | F9: Abo BE | G9: 45769 | K9: =IF(I9<>"",1,0) -> 0 | L9: 4 | M9: 0 | N9: 0 | O9: 0 | P9: =SUM(M9:O9) -> 0 | T9: =P9-Q9 -> 0
A10: PM1 | B10: Sensibilisation cybersecurité - Médaille argent | C10: Niveau 1 | D10: Phished Academy | E10: Axelle ELUAU | F10: Abo BE | G10: 45769 | K10: =IF(I10<>"",1,0) -> 0 | L10: 4 | M10: 0 | O10: 0 | P10: =SUM(M10:O10) -> 0 | T10: =P10-Q10 -> 0
A11: PM1 | B11: Sensibilisation cybersecurité - Médaille or | C11: Niveau 1 | D11: Phished Academy | E11: Caroline MONGET | F11: Abo BE | K11: =IF(I11<>"",1,0) -> 0 | L11: 4 | M11: 0 | O11: 0 | P11: =SUM(M11:O11) -> 0 | T11: =P11-Q11 -> 0
A12: PM1 | B12: Sensibilisation cybersecurité - Médaille or | C12: Niveau 1 | D12: Phished Academy | E12: Michel RACHEDI | F12: Abo BE | K12: =IF(I12<>"",1,0) -> 0 | L12: 4 | M12: 0 | O12: 0 | P12: =SUM(M12:O12) -> 0 | T12: =P12-Q12 -> 0
A13: PM1 | B13: Sensibilisation cybersecurité - Médaille or | C13: Niveau 1 | D13: Phished Academy | E13: Renée DUCHENE | F13: Abo BE | K13: =IF(I13<>"",1,0) -> 0 | L13: 4 | M13: 0 | O13: 0 | P13: =SUM(M13:O13) -> 0 | T13: =P13-Q13 -> 0
A14: PM1 | B14: Sensibilisation cybersecurité - Médaille or | C14: Niveau 1 | D14: Phished Academy | E14: Axelle ELUAU | F14: Abo BE | K14: =IF(I14<>"",1,0) -> 0 | L14: 4 | M14: 0 | O14: 0 | P14: =SUM(M14:O14) -> 0 | T14: =P14-Q14 -> 0
A15: PR2 | B15: ADR 1,3 | C15: Niveau 1 | D15: AFTRAL | E15: Michel RACHEDI | F15: Réglementaire | G15: 13 et 14/11/25 | H15: 25FOR15157 | K15: =IF(I15<>"",1,0) -> 0 | L15: 14 | M15: 713 | P15: =SUM(M15:O15) -> 713 | Q15: 280 | R15: Oui | T15: =P15-Q15 -> 433
A16: PR2 | B16: ADR 1,3 | C16: Niveau 2 | D16: AFTRAL | E16: Renée DUCHENE | F16: Entretien individuel | K16: =IF(I16<>"",1,0) -> 0 | P16: =SUM(M16:O16) -> 0 | T16: =P16-Q16 -> 0
A17: PM1 | B17: Manipulation d'extincteur / Formation équipier 1ére intervention | C17: Niveau 1 | D17: AFTRAL | E17: Caroline MONGET | F17: Réglementaire | K17: =IF(I17<>"",1,0) -> 0 | M17: =990/4 -> 247.5 | P17: =SUM(M17:O17) -> 247.5 | T17: =P17-Q17 -> 247.5
A18: PM1 | B18: Manipulation d'extincteur / Formation équipier 1ére intervention | C18: Niveau 1 | D18: AFTRAL | E18: Michel RACHEDI | F18: Réglementaire | G18: 46042 | K18: =IF(I18<>"",1,0) -> 0 | M18: =990/4 -> 247.5 | P18: =SUM(M18:O18) -> 247.5 | T18: =P18-Q18 -> 247.5
A19: PM1 | B19: Manipulation d'extincteur / Formation équipier 1ére intervention | C19: Niveau 1 | D19: AFTRAL | E19: Renée DUCHENE | F19: Réglementaire | G19: 46042 | K19: =IF(I19<>"",1,0) -> 0 | M19: =990/4 -> 247.5 | P19: =SUM(M19:O19) -> 247.5 | T19: =P19-Q19 -> 247.5
A20: PM1 | B20: Manipulation d'extincteur / Formation équipier 1ére intervention | C20: Niveau 1 | D20: AFTRAL | E20: Axelle ELUAU | F20: Réglementaire | G20: 46042 | K20: =IF(I20<>"",1,0) -> 0 | M20: =990/4 -> 247.5 | P20: =SUM(M20:O20) -> 247.5 | T20: =P20-Q20 -> 247.5
A21: PS1 | B21: SST | C21: Niveau 1 | D21: Croix Rouge | E21: Renée DUCHENE | F21: Réglementaire | G21: Ask date 09/01 | K21: =IF(I21<>"",1,0) -> 0 | P21: =SUM(M21:O21) -> 0 | T21: =P21-Q21 -> 0
A22: PS1 | B22: SST | C22: Niveau 1 | D22: Croix Rouge | E22: Caroline MONGET | F22: Réglementaire | G22: Ask date 09/01 | K22: =IF(I22<>"",1,0) -> 0 | P22: =SUM(M22:O22) -> 0 | T22: =P22-Q22 -> 0
A23: PS1 | B23: SST | C23: Niveau 1 | D23: Croix Rouge | E23: Michel RACHEDI | F23: Réglementaire | G23: Ask date 09/01 | K23: =IF(I23<>"",1,0) -> 0 | P23: =SUM(M23:O23) -> 0 | T23: =P23-Q23 -> 0
A24: PS1 | B24: SST | C24: Niveau 1 | D24: Croix Rouge | E24: Axelle ELUAU | F24: Réglementaire | G24: Ask date 09/01 | K24: =IF(I24<>"",1,0) -> 0 | P24: =SUM(M24:O24) -> 0 | T24: =P24-Q24 -> 0
A25: PR3 | B25: TVA | C25: Niveau 1 | E25: Renée DUCHENE | F25: Entretien individuel | K25: =IF(I25<>"",1,0) -> 0 | P25: =SUM(M25:O25) -> 0 | T25: =P25-Q25 -> 0
A26: PR3 | B26: Nouvelles normes plan comptable | C26: Niveau 1 | E26: Renée DUCHENE | F26: Entretien individuel | K26: =IF(I26<>"",1,0) -> 0 | P26: =SUM(M26:O26) -> 0 | T26: =P26-Q26 -> 0
A27: PS2 | B27: Outlook | C27: Niveau 1 | E27: Renée DUCHENE | F27: Entretien individuel | K27: =IF(I27<>"",1,0) -> 0 | P27: =SUM(M27:O27) -> 0 | T27: =P27-Q27 -> 0
A28: PM1 | B28: Formation cœur de métier | C28: Niveau 1 | E28: Renée DUCHENE | F28: Entretien individuel | K28: =IF(I28<>"",1,0) -> 0 | P28: =SUM(M28:O28) -> 0 | T28: =P28-Q28 -> 0
A29: PM1 | B29: Formation cœur de métier | C29: Niveau 1 | E29: Michel RACHEDI | F29: Entretien individuel | K29: =IF(I29<>"",1,0) -> 0 | P29: =SUM(M29:O29) -> 0 | T29: =P29-Q29 -> 0
A30: PS2 | B30: Access | C30: Niveau 1 | E30: Michel RACHEDI | F30: Entretien individuel | K30: =IF(I30<>"",1,0) -> 0 | P30: =SUM(M30:O30) -> 0 | T30: =P30-Q30 -> 0
K31: =IF(I31<>"",1,0) -> 0 | P31: =SUM(M31:O31) -> 0 | T31: =P31-Q31 -> 0
K32: =IF(I32<>"",1,0) -> 0 | P32: =SUM(M32:O32) -> 0 | T32: =P32-Q32 -> 0
K33: =IF(I33<>"",1,0) -> 0 | P33: =SUM(M33:O33) -> 0 | T33: =P33-Q33 -> 0
K34: =IF(I34<>"",1,0) -> 0 | P34: =SUM(M34:O34) -> 0 | T34: =P34-Q34 -> 0
K35: =IF(I35<>"",1,0) -> 0 | P35: =SUM(M35:O35) -> 0 | T35: =P35-Q35 -> 0
K36: =IF(I36<>"",1,0) -> 0 | P36: =SUM(M36:O36) -> 0 | T36: =P36-Q36 -> 0
K37: =IF(I37<>"",1,0) -> 0 | P37: =SUM(M37:O37) -> 0 | T37: =P37-Q37 -> 0
K38: =IF(I38<>"",1,0) -> 0 | P38: =SUM(M38:O38) -> 0 | T38: =P38-Q38 -> 0
K39: =IF(I39<>"",1,0) -> 0 | P39: =SUM(M39:O39) -> 0 | T39: =P39-Q39 -> 0
K40: =IF(I40<>"",1,0) -> 0 | P40: =SUM(M40:O40) -> 0 | T40: =P40-Q40 -> 0
L43: =SUM(L7:L42) -> 46 | M43: =SUM(M7:M42) -> 1703 | N43: =SUM(N7:N42) -> 0 | O43: =SUM(O7:O42) -> 0 | P43: =SUM(P7:P42) -> 1703 | Q43: =SUM(Q7:Q42) -> 280 | T43: =SUM(T7:T42) -> 1423
G46: Nombre de stages réalisés par salarié :
G47: Michel RACHEDI | H47: =SUMIF($E$7:$E$42,G47,$K$7:$K$42) -> 0
G48: Caroline MONGET | H48: =SUMIF($E$7:$E$42,G48,$K$7:$K$42) -> 0
...

Sheet RGPD_Fichier de violation do
B1: FICHIER DE VIOLATION RGPD
A7: NOM | B7: TITRE | C7: NOM DE L'ORGANISATION | D7: ADRESSE DE L'ORGANISATION NUMÉRO DE TÉLÉPHONE ADRESSE COURRIEL | E7: DATE ET HEURE DE L'ENVOI DE LA NOTIFICATION | F7: DATE ET HEURE DE LA DÉTECTION DE LA VIOLATION DE DONNÉES | G7: TEMPS ÉCOULÉ ENTRE LA DÉTECTION ET LA NOTIFICATION | H7: DESCRIPTION DE LA NATURE DE LA VIOLATION DE DONNÉES À CARACTÈRE PERSONNEL | I7: CONSÉQUENCES PROBABLES DE LA VIOLATION DE DONNÉES | J7: MESURES DÉJÀ PRISES POUR REMÉDIER À L'ATTEINTE | K7: MESURES PROPOSÉES POUR REMÉDIER DAVANTAGE À LA VIOLATION | L7: RAISONS DU RETARD DANS LA NOTIFICATION, S'IL Y A LIEU | M7: ETAT | N7: NOTIFICATION CNIL | O7: NOTIFICATION personne concernée
